Traceback (most recent call last):
  File "C:\Users\almand\Anaconda3\envs\JupyterBook_env\lib\site-packages\jupyter_cache\executors\utils.py", line 51, in single_nb_execution
    executenb(
  File "C:\Users\almand\Anaconda3\envs\JupyterBook_env\lib\site-packages\nbclient\client.py", line 1093, in execute
    return NotebookClient(nb=nb, resources=resources, km=km, **kwargs).execute()
  File "C:\Users\almand\Anaconda3\envs\JupyterBook_env\lib\site-packages\nbclient\util.py", line 84, in wrapped
    return just_run(coro(*args, **kwargs))
  File "C:\Users\almand\Anaconda3\envs\JupyterBook_env\lib\site-packages\nbclient\util.py", line 62, in just_run
    return loop.run_until_complete(coro)
  File "C:\Users\almand\Anaconda3\envs\JupyterBook_env\lib\asyncio\base_events.py", line 642, in run_until_complete
    return future.result()
  File "C:\Users\almand\Anaconda3\envs\JupyterBook_env\lib\site-packages\nbclient\client.py", line 559, in async_execute
    await self.async_execute_cell(
  File "C:\Users\almand\Anaconda3\envs\JupyterBook_env\lib\site-packages\nbclient\client.py", line 854, in async_execute_cell
    self._check_raise_for_error(cell, exec_reply)
  File "C:\Users\almand\Anaconda3\envs\JupyterBook_env\lib\site-packages\nbclient\client.py", line 756, in _check_raise_for_error
    raise CellExecutionError.from_cell_and_msg(cell, exec_reply_content)
nbclient.exceptions.CellExecutionError: An error occurred while executing the following cell:
------------------
f=nc.Dataset('D:/British_Antarctic_Survey/data/GRADES_IMAGE_0607/netcdf/GRADES_IMAGE_G06.nc', 'r')
------------------

[1;31m---------------------------------------------------------------------------[0m
[1;31mFileNotFoundError[0m                         Traceback (most recent call last)
[1;32m<ipython-input-3-54e476869aa7>[0m in [0;36m<module>[1;34m[0m
[1;32m----> 1[1;33m [0mf[0m[1;33m=[0m[0mnc[0m[1;33m.[0m[0mDataset[0m[1;33m([0m[1;34m'D:/British_Antarctic_Survey/data/GRADES_IMAGE_0607/netcdf/GRADES_IMAGE_G06.nc'[0m[1;33m,[0m [1;34m'r'[0m[1;33m)[0m[1;33m[0m[1;33m[0m[0m
[0m
[1;32msrc\netCDF4\_netCDF4.pyx[0m in [0;36mnetCDF4._netCDF4.Dataset.__init__[1;34m()[0m

[1;32msrc\netCDF4\_netCDF4.pyx[0m in [0;36mnetCDF4._netCDF4._ensure_nc_success[1;34m()[0m

[1;31mFileNotFoundError[0m: [Errno 2] No such file or directory: b'D:/British_Antarctic_Survey/data/GRADES_IMAGE_0607/netcdf/GRADES_IMAGE_G06.nc'
FileNotFoundError: [Errno 2] No such file or directory: b'D:/British_Antarctic_Survey/data/GRADES_IMAGE_0607/netcdf/GRADES_IMAGE_G06.nc'

