Traceback (most recent call last):
  File "C:\Users\almand\AppData\Local\miniforge3\envs\gloria_env\Lib\site-packages\jupyter_cache\executors\utils.py", line 58, in single_nb_execution
    executenb(
    ~~~~~~~~~^
        nb,
        ^^^
    ...<4 lines>...
        **kwargs,
        ^^^^^^^^^
    )
    ^
  File "C:\Users\almand\AppData\Local\miniforge3\envs\gloria_env\Lib\site-packages\nbclient\client.py", line 1319, in execute
    return NotebookClient(nb=nb, resources=resources, km=km, **kwargs).execute()
           ~~~~~~~~~~~~~~~~~~~~~~~~~~~~~~~~~~~~~~~~~~~~~~~~~~~~~~~~~~~~~~~~~~~^^
  File "C:\Users\almand\AppData\Local\miniforge3\envs\gloria_env\Lib\site-packages\jupyter_core\utils\__init__.py", line 165, in wrapped
    return loop.run_until_complete(inner)
           ~~~~~~~~~~~~~~~~~~~~~~~^^^^^^^
  File "C:\Users\almand\AppData\Local\miniforge3\envs\gloria_env\Lib\asyncio\base_events.py", line 725, in run_until_complete
    return future.result()
           ~~~~~~~~~~~~~^^
  File "C:\Users\almand\AppData\Local\miniforge3\envs\gloria_env\Lib\site-packages\nbclient\client.py", line 709, in async_execute
    await self.async_execute_cell(
        cell, index, execution_count=self.code_cells_executed + 1
    )
  File "C:\Users\almand\AppData\Local\miniforge3\envs\gloria_env\Lib\site-packages\nbclient\client.py", line 1062, in async_execute_cell
    await self._check_raise_for_error(cell, cell_index, exec_reply)
  File "C:\Users\almand\AppData\Local\miniforge3\envs\gloria_env\Lib\site-packages\nbclient\client.py", line 918, in _check_raise_for_error
    raise CellExecutionError.from_cell_and_msg(cell, exec_reply_content)
nbclient.exceptions.CellExecutionError: An error occurred while executing the following cell:
------------------
f = "CD37_GLORIA_PASS169.nc"
fnc = nc.Dataset(f)

print(fnc.ncattrs())
------------------


[1;31m---------------------------------------------------------------------------[0m
[1;31mFileNotFoundError[0m                         Traceback (most recent call last)
Cell [1;32mIn[5], line 2[0m
[0;32m      1[0m f [38;5;241m=[39m [38;5;124m"[39m[38;5;124mCD37_GLORIA_PASS169.nc[39m[38;5;124m"[39m
[1;32m----> 2[0m fnc [38;5;241m=[39m [43mnc[49m[38;5;241;43m.[39;49m[43mDataset[49m[43m([49m[43mf[49m[43m)[49m
[0;32m      4[0m [38;5;28mprint[39m(fnc[38;5;241m.[39mncattrs())

File [1;32msrc\\netCDF4\\_netCDF4.pyx:2521[0m, in [0;36mnetCDF4._netCDF4.Dataset.__init__[1;34m()[0m

File [1;32msrc\\netCDF4\\_netCDF4.pyx:2158[0m, in [0;36mnetCDF4._netCDF4._ensure_nc_success[1;34m()[0m

[1;31mFileNotFoundError[0m: [Errno 2] No such file or directory: 'CD37_GLORIA_PASS169.nc'

