Traceback (most recent call last):
  File "C:\Users\almand\AppData\Local\miniforge3\envs\gloria_env\Lib\site-packages\jupyter_cache\executors\utils.py", line 58, in single_nb_execution
    executenb(
    ~~~~~~~~~^
        nb,
        ^^^
    ...<4 lines>...
        **kwargs,
        ^^^^^^^^^
    )
    ^
  File "C:\Users\almand\AppData\Local\miniforge3\envs\gloria_env\Lib\site-packages\nbclient\client.py", line 1319, in execute
    return NotebookClient(nb=nb, resources=resources, km=km, **kwargs).execute()
           ~~~~~~~~~~~~~~~~~~~~~~~~~~~~~~~~~~~~~~~~~~~~~~~~~~~~~~~~~~~~~~~~~~~^^
  File "C:\Users\almand\AppData\Local\miniforge3\envs\gloria_env\Lib\site-packages\jupyter_core\utils\__init__.py", line 165, in wrapped
    return loop.run_until_complete(inner)
           ~~~~~~~~~~~~~~~~~~~~~~~^^^^^^^
  File "C:\Users\almand\AppData\Local\miniforge3\envs\gloria_env\Lib\asyncio\base_events.py", line 725, in run_until_complete
    return future.result()
           ~~~~~~~~~~~~~^^
  File "C:\Users\almand\AppData\Local\miniforge3\envs\gloria_env\Lib\site-packages\nbclient\client.py", line 709, in async_execute
    await self.async_execute_cell(
        cell, index, execution_count=self.code_cells_executed + 1
    )
  File "C:\Users\almand\AppData\Local\miniforge3\envs\gloria_env\Lib\site-packages\nbclient\client.py", line 1062, in async_execute_cell
    await self._check_raise_for_error(cell, cell_index, exec_reply)
  File "C:\Users\almand\AppData\Local\miniforge3\envs\gloria_env\Lib\site-packages\nbclient\client.py", line 918, in _check_raise_for_error
    raise CellExecutionError.from_cell_and_msg(cell, exec_reply_content)
nbclient.exceptions.CellExecutionError: An error occurred while executing the following cell:
------------------
import netCDF4 as nc
from obspy.io.segy.segy import _read_segy
import matplotlib.pyplot as plt
import matplotlib.ticker as ticker
from matplotlib import transforms
import numpy as np
------------------


[1;31m---------------------------------------------------------------------------[0m
[1;31mModuleNotFoundError[0m                       Traceback (most recent call last)
Cell [1;32mIn[2], line 2[0m
[0;32m      1[0m [38;5;28;01mimport[39;00m[38;5;250m [39m[38;5;21;01mnetCDF4[39;00m[38;5;250m [39m[38;5;28;01mas[39;00m[38;5;250m [39m[38;5;21;01mnc[39;00m
[1;32m----> 2[0m [38;5;28;01mfrom[39;00m[38;5;250m [39m[38;5;21;01mobspy[39;00m[38;5;21;01m.[39;00m[38;5;21;01mio[39;00m[38;5;21;01m.[39;00m[38;5;21;01msegy[39;00m[38;5;21;01m.[39;00m[38;5;21;01msegy[39;00m[38;5;250m [39m[38;5;28;01mimport[39;00m _read_segy
[0;32m      3[0m [38;5;28;01mimport[39;00m[38;5;250m [39m[38;5;21;01mmatplotlib[39;00m[38;5;21;01m.[39;00m[38;5;21;01mpyplot[39;00m[38;5;250m [39m[38;5;28;01mas[39;00m[38;5;250m [39m[38;5;21;01mplt[39;00m
[0;32m      4[0m [38;5;28;01mimport[39;00m[38;5;250m [39m[38;5;21;01mmatplotlib[39;00m[38;5;21;01m.[39;00m[38;5;21;01mticker[39;00m[38;5;250m [39m[38;5;28;01mas[39;00m[38;5;250m [39m[38;5;21;01mticker[39;00m

[1;31mModuleNotFoundError[0m: No module named 'obspy'

