Traceback (most recent call last):
  File "C:\Users\almand\AppData\Local\miniforge3\envs\gloria_env\Lib\site-packages\jupyter_cache\executors\utils.py", line 58, in single_nb_execution
    executenb(
    ~~~~~~~~~^
        nb,
        ^^^
    ...<4 lines>...
        **kwargs,
        ^^^^^^^^^
    )
    ^
  File "C:\Users\almand\AppData\Local\miniforge3\envs\gloria_env\Lib\site-packages\nbclient\client.py", line 1319, in execute
    return NotebookClient(nb=nb, resources=resources, km=km, **kwargs).execute()
           ~~~~~~~~~~~~~~~~~~~~~~~~~~~~~~~~~~~~~~~~~~~~~~~~~~~~~~~~~~~~~~~~~~~^^
  File "C:\Users\almand\AppData\Local\miniforge3\envs\gloria_env\Lib\site-packages\jupyter_core\utils\__init__.py", line 165, in wrapped
    return loop.run_until_complete(inner)
           ~~~~~~~~~~~~~~~~~~~~~~~^^^^^^^
  File "C:\Users\almand\AppData\Local\miniforge3\envs\gloria_env\Lib\asyncio\base_events.py", line 725, in run_until_complete
    return future.result()
           ~~~~~~~~~~~~~^^
  File "C:\Users\almand\AppData\Local\miniforge3\envs\gloria_env\Lib\site-packages\nbclient\client.py", line 709, in async_execute
    await self.async_execute_cell(
        cell, index, execution_count=self.code_cells_executed + 1
    )
  File "C:\Users\almand\AppData\Local\miniforge3\envs\gloria_env\Lib\site-packages\nbclient\client.py", line 1062, in async_execute_cell
    await self._check_raise_for_error(cell, cell_index, exec_reply)
  File "C:\Users\almand\AppData\Local\miniforge3\envs\gloria_env\Lib\site-packages\nbclient\client.py", line 918, in _check_raise_for_error
    raise CellExecutionError.from_cell_and_msg(cell, exec_reply_content)
nbclient.exceptions.CellExecutionError: An error occurred while executing the following cell:
------------------
import numpy as np
import gdal
import pandas as pd
import os
import glob
import math
from scipy.stats import iqr
import geopandas as gpd
from pathlib import Path
import warnings

from ll2ps_projection import stereosouth_lonlat2xy# for lon/lat to xy projection (see stereosouth_xy2lonlat function)
------------------


[1;31m---------------------------------------------------------------------------[0m
[1;31mModuleNotFoundError[0m                       Traceback (most recent call last)
Cell [1;32mIn[2], line 2[0m
[0;32m      1[0m [38;5;28;01mimport[39;00m[38;5;250m [39m[38;5;21;01mnumpy[39;00m[38;5;250m [39m[38;5;28;01mas[39;00m[38;5;250m [39m[38;5;21;01mnp[39;00m
[1;32m----> 2[0m [38;5;28;01mimport[39;00m[38;5;250m [39m[38;5;21;01mgdal[39;00m
[0;32m      3[0m [38;5;28;01mimport[39;00m[38;5;250m [39m[38;5;21;01mpandas[39;00m[38;5;250m [39m[38;5;28;01mas[39;00m[38;5;250m [39m[38;5;21;01mpd[39;00m
[0;32m      4[0m [38;5;28;01mimport[39;00m[38;5;250m [39m[38;5;21;01mos[39;00m

[1;31mModuleNotFoundError[0m: No module named 'gdal'

